Workbook

Sheet Companies
A1: company_id | B1: ticker | C1: company_name | D1: sector | E1: asset_class
A2: 1 | B2: AAPL | C2: Apple Inc. | D2: Technology | E2: Equity
A3: 2 | B3: MSFT | C3: Microsoft Corp. | D3: Technology | E3: Equity
A4: 3 | B4: JNJ | C4: Johnson & Johnson | D4: Healthcare | E4: Equity
A5: 4 | B5: PFE | C5: Pfizer Inc. | D5: Healthcare | E5: Equity
A6: 5 | B6: JPM | C6: JPMorgan Chase & Co. | D6: Financials | E6: Equity
A7: 6 | B7: GS | C7: Goldman Sachs Group | D7: Financials | E7: Equity
A8: 7 | B8: XOM | C8: Exxon Mobil Corp. | D8: Energy | E8: Equity
A9: 8 | B9: CVX | C9: Chevron Corp. | D9: Energy | E9: Equity
A10: 9 | B10: PG | C10: Procter & Gamble | D10: Consumer Goods | E10: Equity
A11: 10 | B11: KO | C11: Coca-Cola Co. | D11: Consumer Goods | E11: Equity
A12: 11 | B12: SPY | C12: SPDR S&P 500 ETF | D12: Diversified | E12: ETF
A13: 12 | B13: AGG | C13: iShares Core US Bond ETF | D13: Fixed Income | E13: Bond
... A16: 15 | B16: UUP | C16: Invesco DB US Dollar Index | D16: Currency | E16: Currency

Sheet Stock_Prices
A1: price_id | B1: company_id | C1: trade_date | D1: open_price | E1: high_price | F1: low_price | G1: close_price | H1: volume | I1: prev_close_ref_row | J1: daily_return_pct | K1: key
A2: 1 | B2: 1 | C2: 2024-01-02 | D2: 272.13 | E2: 272.14 | F2: 270.14 | G2: 271.46 | H2: 5736045 | K2: =B2&"_"&C2 -> 1_2024-01-02
A3: 2 | B3: 1 | C3: 2024-01-03 | D3: 277.57 | E3: 278.19 | F3: 275.98 | G3: 277.93 | H3: 3024459 | J3: =ROUND((G3-G2)/G2*100,2) -> 2.38 | K3: =B3&"_"&C3 -> 1_2024-01-03
A4: 3 | B4: 1 | C4: 2024-01-04 | D4: 280.65 | E4: 281.67 | F4: 278.52 | G4: 279.88 | H4: 5972988 | J4: =ROUND((G4-G3)/G3*100,2) -> 0.7 | K4: =B4&"_"&C4 -> 1_2024-01-04
A5: 4 | B5: 1 | C5: 2024-01-05 | D5: 281.27 | E5: 282.92 | F5: 280.55 | G5: 281.19 | H5: 4640304 | J5: =ROUND((G5-G4)/G4*100,2) -> 0.47 | K5: =B5&"_"&C5 -> 1_2024-01-05
A6: 5 | B6: 1 | C6: 2024-01-08 | D6: 285.44 | E6: 286.43 | F6: 283.42 | G6: 284.62 | H6: 843682 | J6: =ROUND((G6-G5)/G5*100,2) -> 1.22 | K6: =B6&"_"&C6 -> 1_2024-01-08
A7: 6 | B7: 1 | C7: 2024-01-09 | D7: 277.84 | E7: 278.93 | F7: 277.7 | G7: 278.44 | H7: 2245931 | J7: =ROUND((G7-G6)/G6*100,2) -> -2.17 | K7: =B7&"_"&C7 -> 1_2024-01-09
A8: 7 | B8: 1 | C8: 2024-01-10 | D8: 282.07 | E8: 282.69 | F8: 281.14 | G8: 281.77 | H8: 2071302 | J8: =ROUND((G8-G7)/G7*100,2) -> 1.2 | K8: =B8&"_"&C8 -> 1_2024-01-10
A9: 8 | B9: 1 | C9: 2024-01-11 | D9: 283.73 | E9: 285.86 | F9: 282.63 | G9: 284.26 | H9: 5068482 | J9: =ROUND((G9-G8)/G8*100,2) -> 0.88 | K9: =B9&"_"&C9 -> 1_2024-01-11
A10: 9 | B10: 1 | C10: 2024-01-12 | D10: 287.48 | E10: 288.91 | F10: 285.77 | G10: 288.26 | H10: 5299998 | J10: =ROUND((G10-G9)/G9*100,2) -> 1.41 | K10: =B10&"_"&C10 -> 1_2024-01-12
A11: 10 | B11: 1 | C11: 2024-01-15 | D11: 295.84 | E11: 297.05 | F11: 294.21 | G11: 295.7 | H11: 6319999 | J11: =ROUND((G11-G10)/G10*100,2) -> 2.58 | K11: =B11&"_"&C11 -> 1_2024-01-15
A12: 11 | B12: 1 | C12: 2024-01-16 | D12: 295.51 | E12: 296.43 | F12: 295.14 | G12: 295.95 | H12: 7571822 | J12: =ROUND((G12-G11)/G11*100,2) -> 0.08 | K12: =B12&"_"&C12 -> 1_2024-01-16
A13: 12 | B13: 1 | C13: 2024-01-17 | D13: 298.27 | E13: 298.83 | F13: 296.2 | G13: 297.37 | H13: 3467239 | J13: =ROUND((G13-G12)/G12*100,2) -> 0.48 | K13: =B13&"_"&C13 -> 1_2024-01-17
A14: 13 | B14: 1 | C14: 2024-01-18 | D14: 301.97 | E14: 302.99 | F14: 300.95 | G14: 302.54 | H14: 2470562 | J14: =ROUND((G14-G13)/G13*100,2) -> 1.74 | K14: =B14&"_"&C14 -> 1_2024-01-18
... A501: 500 | B501: 1 | C501: 2025-12-01 | D501: 326.03 | E501: 326.75 | F501: 323.04 | G501: 324.9 | H501: 2954669 | J501: =ROUND((G501-G500)/G500*100,2) -> 0.78 | K501: =B501&"_"&C501 -> 1_2025-12-01
A502: 501 | B502: 2 | C502: 2024-01-02 | D502: 49.3 | E502: 49.44 | F502: 49.01 | G502: 49.21 | H502: 3186670 | K502: =B502&"_"&C502 -> 2_2024-01-02
A503: 502 | B503: 2 | C503: 2024-01-03 | D503: 47.61 | E503: 47.93 | F503: 47.55 | G503: 47.78 | H503: 3722323 | J503: =ROUND((G503-G502)/G502*100,2) -> -2.91 | K503: =B503&"_"&C503 -> 2_2024-01-03
A504: 503 | B504: 2 | C504: 2024-01-04 | D504: 48.06 | E504: 48.15 | F504: 47.76 | G504: 47.93 | H504: 4746065 | J504: =ROUND((G504-G503)/G503*100,2) -> 0.31 | K504: =B504&"_"&C504 -> 2_2024-01-04
A505: 504 | B505: 2 | C505: 2024-01-05 | D505: 48.58 | E505: 48.68 | F505: 48.38 | G505: 48.58 | H505: 863069 | J505: =ROUND((G505-G504)/G504*100,2) -> 1.36 | K505: =B505&"_"&C505 -> 2_2024-01-05
A506: 505 | B506: 2 | C506: 2024-01-08 | D506: 49.8 | E506: 49.85 | F506: 49.54 | G506: 49.81 | H506: 3809644 | J506: =ROUND((G506-G505)/G505*100,2) -> 2.53 | K506: =B506&"_"&C506 -> 2_2024-01-08
A507: 506 | B507: 2 | C507: 2024-01-09 | D507: 50.52 | E507: 51.02 | F507: 50.46 | G507: 50.72 | H507: 5664439 | J507: =ROUND((G507-G506)/G506*100,2) -> 1.83 | K507: =B507&"_"&C507 -> 2_2024-01-09
A508: 507 | B508: 2 | C508: 2024-01-10 | D508: 51.47 | E508: 51.9 | F508: 51.38 | G508: 51.61 | H508: 5409409 | J508: =ROUND((G508-G507)/G507*100,2) -> 1.75 | K508: =B508&"_"&C508 -> 2_2024-01-10
A509: 508 | B509: 2 | C509: 2024-01-11 | D509: 52.49 | E509: 52.71 | F509: 52.2 | G509: 52.59 | H509: 1741438 | J509: =ROUND((G509-G508)/G508*100,2) -> 1.9 | K509: =B509&"_"&C509 -> 2_2024-01-11
A510: 509 | B510: 2 | C510: 2024-01-12 | D510: 52.02 | E510: 52.09 | F510: 51.73 | G510: 51.94 | H510: 5777735 | J510: =ROUND((G510-G509)/G509*100,2) -> -1.24 | K510: =B510&"_"&C510 -> 2_2024-01-12
A511: 510 | B511: 2 | C511: 2024-01-15 | D511: 52.2 | E511: 52.56 | F511: 52.16 | G511: 52.41 | H511: 2196431 | J511: =ROUND((G511-G510)/G510*100,2) -> 0.9 | K511: =B511&"_"&C511 -> 2_2024-01-15
A512: 511 | B512: 2 | C512: 2024-01-16 | D512: 52.43 | E512: 52.68 | F512: 52.03 | G512: 52.35 | H512: 3667354 | J512: =ROUND((G512-G511)/G511*100,2) -> -0.11 | K512: =B512&"_"&C512 -> 2_2024-01-16
A513: 512 | B513: 2 | C513: 2024-01-17 | D513: 52.06 | E513: 52.24 | F513: 51.95 | G513: 52.22 | H513: 5980725 | J513: =ROUND((G513-G512)/G512*100,2) -> -0.25 | K513: =B513&"_"&C513 -> 2_2024-01-17
A514: 513 | B514: 2 | C514: 2024-01-18 | D514: 53.02 | E514: 53.06 | F514: 52.61 | G514: 52.86 | H514: 6148683 | J514: =ROUND((G514-G513)/G513*100,2) -> 1.23 | K514: =B514&"_"&C514 -> 2_2024-01-18
... A1001: 1000 | B1001: 2 | C1001: 2025-12-01 | D1001: 27.29 | E1001: 27.42 | F1001: 27.05 | G1001: 27.21 | H1001: 3605308 | J1001: =ROUND((G1001-G1000)/G1000*100,2) -> -4.86 | K1001: =B1001&"_"&C1001 -> 2_2025-12-01
A1002: 1001 | B1002: 3 | C1002: 2024-01-02 | D1002: 135.18 | E1002: 135.87 | F1002: 134.95 | G1002: 135.71 | H1002: 6426466 | K1002: =B1002&"_"&C1002 -> 3_2024-01-02
A1003: 1002 | B1003: 3 | C1003: 2024-01-03 | D1003: 134.22 | E1003: 134.84 | F1003: 133.96 | G1003: 134.43 | H1003: 545984 | J1003: =ROUND((G1003-G1002)/G1002*100,2) -> -0.94 | K1003: =B1003&"_"&C1003 -> 3_2024-01-03
A1004: 1003 | B1004: 3 | C1004: 2024-01-04 | D1004: 133.81 | E1004: 134.3 | F1004: 133.55 | G1004: 133.57 | H1004: 1817218 | J1004: =ROUND((G1004-G1003)/G1003*100,2) -> -0.64 | K1004: =B1004&"_"&C1004 -> 3_2024-01-04
A1005: 1004 | B1005: 3 | C1005: 2024-01-05 | D1005: 131.38 | E1005: 131.82 | F1005: 130.85 | G1005: 131.56 | H1005: 7371222 | J1005: =ROUND((G1005-G1004)/G1004*100,2) -> -1.5 | K1005: =B1005&"_"&C1005 -> 3_2024-01-05
A1006: 1005 | B1006: 3 | C1006: 2024-01-08 | D1006: 132.55 | E1006: 133.06 | F1006: 131.84 | G1006: 132.56 | H1006: 4527256 | J1006: =ROUND((G1006-G1005)/G1005*100,2) -> 0.76 | K1006: =B1006&"_"&C1006 -> 3_2024-01-08
A1007: 1006 | B1007: 3 | C1007: 2024-01-09 | D1007: 129.12 | E1007: 129.9 | F1007: 128.8 | G1007: 129.29 | H1007: 6069384 | J1007: =ROUND((G1007-G1006)/G1006*100,2) -> -2.47 | K1007: =B1007&"_"&C1007 -> 3_2024-01-09
A1008: 1007 | B1008: 3 | C1008: 2024-01-10 | D1008: 130.53 | E1008: 130.78 | F1008: 129.88 | G1008: 130.3 | H1008: 2061968 | J1008: =ROUND((G1008-G1007)/G1007*100,2) -> 0.78 | K1008: =B1008&"_"&C1008 -> 3_2024-01-10
A1009: 1008 | B1009: 3 | C1009: 2024-01-11 | D1009: 128.79 | E1009: 129.41 | F1009: 127.92 | G1009: 128.6 | H1009: 3151966 | J1009: =ROUND((G1009-G1008)/G1008*100,2) -> -1.3 | K1009: =B1009&"_"&C1009 -> 3_2024-01-11
A1010: 1009 | B1010: 3 | C1010: 2024-01-12 | D1010: 129.97 | E1010: 131.23 | F1010: 129.48 | G1010: 130.46 | H1010: 6818043 | J1010: =ROUND((G1010-G1009)/G1009*100,2) -> 1.45 | K1010: =B1010&"_"&C1010 -> 3_2024-01-12
A1011: 1010 | B1011: 3 | C1011: 2024-01-15 | D1011: 130.18 | E1011: 130.48 | F1011: 129.64 | G1011: 130.1 | H1011: 6984452 | J1011: =ROUND((G1011-G1010)/G1010*100,2) -> -0.28 | K1011: =B1011&"_"&C1011 -> 3_2024-01-15
A1012: 1011 | B1012: 3 | C1012: 2024-01-16 | D1012: 129.95 | E1012: 130.17 | F1012: 129.63 | G1012: 130.15 | H1012: 4227908 | J1012: =ROUND((G1012-G1011)/G1011*100,2) -> 0.04 | K1012: =B1012&"_"&C1012 -> 3_2024-01-16
...

Sheet Transactions
A1: transaction_id | B1: company_id | C1: trade_date | D1: transaction_type | E1: quantity | F1: price | G1: asset_class | H1: trade_value
A2: 1 | B2: 5 | C2: 2024-01-02 | D2: BUY | E2: 928 | F2: 306.03 | G2: Equity | H2: =ROUND(E2*F2,2) -> 283995.84
A3: 2 | B3: 11 | C3: 2024-01-02 | D3: BUY | E3: 4521 | F3: 119.88 | G3: ETF | H3: =ROUND(E3*F3,2) -> 541977.48
A4: 3 | B4: 14 | C4: 2024-01-02 | D4: SELL | E4: 4018 | F4: 109.75 | G4: Commodity | H4: =ROUND(E4*F4,2) -> 440975.5
A5: 4 | B5: 6 | C5: 2024-01-02 | D5: SELL | E5: 1932 | F5: 275.89 | G5: Equity | H5: =ROUND(E5*F5,2) -> 533019.48
A6: 5 | B6: 9 | C6: 2024-01-02 | D6: SELL | E6: 2560 | F6: 194.24 | G6: Equity | H6: =ROUND(E6*F6,2) -> 497254.4
A7: 6 | B7: 5 | C7: 2024-01-02 | D7: SELL | E7: 4483 | F7: 305.58 | G7: Equity | H7: =ROUND(E7*F7,2) -> 1369915.1
A8: 7 | B8: 8 | C8: 2024-01-02 | D8: BUY | E8: 2218 | F8: 71.68 | G8: Equity | H8: =ROUND(E8*F8,2) -> 158986.24
A9: 8 | B9: 4 | C9: 2024-01-02 | D9: SELL | E9: 3377 | F9: 122.73 | G9: Equity | H9: =ROUND(E9*F9,2) -> 414459.21
A10: 9 | B10: 14 | C10: 2024-01-02 | D10: BUY | E10: 3926 | F10: 109.8 | G10: Commodity | H10: =ROUND(E10*F10,2) -> 431074.8
A11: 10 | B11: 6 | C11: 2024-01-02 | D11: SELL | E11: 149 | F11: 275.3 | G11: Equity | H11: =ROUND(E11*F11,2) -> 41019.7
A12: 11 | B12: 15 | C12: 2024-01-02 | D12: SELL | E12: 4467 | F12: 274.7 | G12: Currency | H12: =ROUND(E12*F12,2) -> 1227084.9
A13: 12 | B13: 8 | C13: 2024-01-02 | D13: SELL | E13: 326 | F13: 71.36 | G13: Equity | H13: =ROUND(E13*F13,2) -> 23263.36
... A14904: 14903 | B14904: 15 | C14904: 2025-12-01 | D14904: SELL | E14904: 3736 | F14904: 291.53 | G14904: Currency | H14904: =ROUND(E14904*F14904,2) -> 1089156.1

Sheet Quarterly_Returns
A1: company_id | B1: ticker | C1: year | D1: quarter | E1: quarter_index | F1: start_date | G1: end_date | H1: start_price | I1: end_price | J1: quarterly_return_pct
A2: 1 | B2: AAPL | C2: 2024 | D2: 1 | E2: 1 | F2: 2024-01-02 | G2: 2024-03-29 | H2: =INDEX(Stock_Prices!$G$2:$G$7501,MATCH("1_2024-01-02",Stock_Prices!$K$2:$K$7501,0)) -> 271.46 | I2: =INDEX(Stock_Prices!$G$2:$G$7501,MATCH("1_2024-03-29",Stock_Prices!$K$2:$K$7501,0)) -> 345.85 | J2: =ROUND((I2-H2)/H2*100,2) -> 27.4
A3: 1 | B3: AAPL | C3: 2024 | D3: 2 | E3: 2 | F3: 2024-04-01 | G3: 2024-06-28 | H3: =INDEX(Stock_Prices!$G$2:$G$7501,MATCH("1_2024-04-01",Stock_Prices!$K$2:$K$7501,0)) -> 347.91 | I3: =INDEX(Stock_Prices!$G$2:$G$7501,MATCH("1_2024-06-28",Stock_Prices!$K$2:$K$7501,0)) -> 450.72 | J3: =ROUND((I3-H3)/H3*100,2) -> 29.55
A4: 1 | B4: AAPL | C4: 2024 | D4: 3 | E4: 3 | F4: 2024-07-01 | G4: 2024-09-30 | H4: =INDEX(Stock_Prices!$G$2:$G$7501,MATCH("1_2024-07-01",Stock_Prices!$K$2:$K$7501,0)) -> 455.95 | I4: =INDEX(Stock_Prices!$G$2:$G$7501,MATCH("1_2024-09-30",Stock_Prices!$K$2:$K$7501,0)) -> 405.21 | J4: =ROUND((I4-H4)/H4*100,2) -> -11.13
A5: 1 | B5: AAPL | C5: 2024 | D5: 4 | E5: 4 | F5: 2024-10-01 | G5: 2024-12-31 | H5: =INDEX(Stock_Prices!$G$2:$G$7501,MATCH("1_2024-10-01",Stock_Prices!$K$2:$K$7501,0)) -> 402.78 | I5: =INDEX(Stock_Prices!$G$2:$G$7501,MATCH("1_2024-12-31",Stock_Prices!$K$2:$K$7501,0)) -> 396.54 | J5: =ROUND((I5-H5)/H5*100,2) -> -1.55
A6: 1 | B6: AAPL | C6: 2025 | D6: 1 | E6: 5 | F6: 2025-01-01 | G6: 2025-03-31 | H6: =INDEX(Stock_Prices!$G$2:$G$7501,MATCH("1_2025-01-01",Stock_Prices!$K$2:$K$7501,0)) -> 403.05 | I6: =INDEX(Stock_Prices!$G$2:$G$7501,MATCH("1_2025-03-31",Stock_Prices!$K$2:$K$7501,0)) -> 392.44 | J6: =ROUND((I6-H6)/H6*100,2) -> -2.63
A7: 1 | B7: AAPL | C7: 2025 | D7: 2 | E7: 6 | F7: 2025-04-01 | G7: 2025-06-30 | H7: =INDEX(Stock_Prices!$G$2:$G$7501,MATCH("1_2025-04-01",Stock_Prices!$K$2:$K$7501,0)) -> 399.12 | I7: =INDEX(Stock_Prices!$G$2:$G$7501,MATCH("1_2025-06-30",Stock_Prices!$K$2:$K$7501,0)) -> 447.74 | J7: =ROUND((I7-H7)/H7*100,2) -> 12.18
A8: 1 | B8: AAPL | C8: 2025 | D8: 3 | E8: 7 | F8: 2025-07-01 | G8: 2025-09-30 | H8: =INDEX(Stock_Prices!$G$2:$G$7501,MATCH("1_2025-07-01",Stock_Prices!$K$2:$K$7501,0)) -> 433.14 | I8: =INDEX(Stock_Prices!$G$2:$G$7501,MATCH("1_2025-09-30",Stock_Prices!$K$2:$K$7501,0)) -> 317.6 | J8: =ROUND((I8-H8)/H8*100,2) -> -26.67
A9: 1 | B9: AAPL | C9: 2025 | D9: 4 | E9: 8 | F9: 2025-10-01 | G9: 2025-12-01 | H9: =INDEX(Stock_Prices!$G$2:$G$7501,MATCH("1_2025-10-01",Stock_Prices!$K$2:$K$7501,0)) -> 321.95 | I9: =INDEX(Stock_Prices!$G$2:$G$7501,MATCH("1_2025-12-01",Stock_Prices!$K$2:$K$7501,0)) -> 324.9 | J9: =ROUND((I9-H9)/H9*100,2) -> 0.92
A10: 2 | B10: MSFT | C10: 2024 | D10: 1 | E10: 1 | F10: 2024-01-02 | G10: 2024-03-29 | H10: =INDEX(Stock_Prices!$G$2:$G$7501,MATCH("2_2024-01-02",Stock_Prices!$K$2:$K$7501,0)) -> 49.21 | I10: =INDEX(Stock_Prices!$G$2:$G$7501,MATCH("2_2024-03-29",Stock_Prices!$K$2:$K$7501,0)) -> 64.35 | J10: =ROUND((I10-H10)/H10*100,2) -> 30.77
A11: 2 | B11: MSFT | C11: 2024 | D11: 2 | E11: 2 | F11: 2024-04-01 | G11: 2024-06-28 | H11: =INDEX(Stock_Prices!$G$2:$G$7501,MATCH("2_2024-04-01",Stock_Prices!$K$2:$K$7501,0)) -> 66.64 | I11: =INDEX(Stock_Prices!$G$2:$G$7501,MATCH("2_2024-06-28",Stock_Prices!$K$2:$K$7501,0)) -> 64.33 | J11: =ROUND((I11-H11)/H11*100,2) -> -3.47
A12: 2 | B12: MSFT | C12: 2024 | D12: 3 | E12: 3 | F12: 2024-07-01 | G12: 2024-09-30 | H12: =INDEX(Stock_Prices!$G$2:$G$7501,MATCH("2_2024-07-01",Stock_Prices!$K$2:$K$7501,0)) -> 66.41 | I12: =INDEX(Stock_Prices!$G$2:$G$7501,MATCH("2_2024-09-30",Stock_Prices!$K$2:$K$7501,0)) -> 56.39 | J12: =ROUND((I12-H12)/H12*100,2) -> -15.09
A13: 2 | B13: MSFT | C13: 2024 | D13: 4 | E13: 4 | F13: 2024-10-01 | G13: 2024-12-31 | H13: =INDEX(Stock_Prices!$G$2:$G$7501,MATCH("2_2024-10-01",Stock_Prices!$K$2:$K$7501,0)) -> 57.66 | I13: =INDEX(Stock_Prices!$G$2:$G$7501,MATCH("2_2024-12-31",Stock_Prices!$K$2:$K$7501,0)) -> 49.02 | J13: =ROUND((I13-H13)/H13*100,2) -> -14.98
A14: 2 | B14: MSFT | C14: 2025 | D14: 1 | E14: 5 | F14: 2025-01-01 | G14: 2025-03-31 | H14: =INDEX(Stock_Prices!$G$2:$G$7501,MATCH("2_2025-01-01",Stock_Prices!$K$2:$K$7501,0)) -> 47.36 | I14: =INDEX(Stock_Prices!$G$2:$G$7501,MATCH("2_2025-03-31",Stock_Prices!$K$2:$K$7501,0)) -> 36.96 | J14: =ROUND((I14-H14)/H14*100,2) -> -21.96
A15: 2 | B15: MSFT | C15: 2025 | D15: 2 | E15: 6 | F15: 2025-04-01 | G15: 2025-06-30 | H15: =INDEX(Stock_Prices!$G$2:$G$7501,MATCH("2_2025-04-01",Stock_Prices!$K$2:$K$7501,0)) -> 35.26 | I15: =INDEX(Stock_Prices!$G$2:$G$7501,MATCH("2_2025-06-30",Stock_Prices!$K$2:$K$7501,0)) -> 30.22 | J15: =ROUND((I15-H15)/H15*100,2) -> -14.29
A16: 2 | B16: MSFT | C16: 2025 | D16: 3 | E16: 7 | F16: 2025-07-01 | G16: 2025-09-30 | H16: =INDEX(Stock_Prices!$G$2:$G$7501,MATCH("2_2025-07-01",Stock_Prices!$K$2:$K$7501,0)) -> 30.28 | I16: =INDEX(Stock_Prices!$G$2:$G$7501,MATCH("2_2025-09-30",Stock_Prices!$K$2:$K$7501,0)) -> 31.29 | J16: =ROUND((I16-H16)/H16*100,2) -> 3.34
A17: 2 | B17: MSFT | C17: 2025 | D17: 4 | E17: 8 | F17: 2025-10-01 | G17: 2025-12-01 | H17: =INDEX(Stock_Prices!$G$2:$G$7501,MATCH("2_2025-10-01",Stock_Prices!$K$2:$K$7501,0)) -> 32.43 | I17: =INDEX(Stock_Prices!$G$2:$G$7501,MATCH("2_2025-12-01",Stock_Prices!$K$2:$K$7501,0)) -> 27.21 | J17: =ROUND((I17-H17)/H17*100,2) -> -16.1
A18: 3 | B18: JNJ | C18: 2024 | D18: 1 | E18: 1 | F18: 2024-01-02 | G18: 2024-03-29 | H18: =INDEX(Stock_Prices!$G$2:$G$7501,MATCH("3_2024-01-02",Stock_Prices!$K$2:$K$7501,0)) -> 135.71 | I18: =INDEX(Stock_Prices!$G$2:$G$7501,MATCH("3_2024-03-29",Stock_Prices!$K$2:$K$7501,0)) -> 107.71 | J18: =ROUND((I18-H18)/H18*100,2) -> -20.63
A19: 3 | B19: JNJ | C19: 2024 | D19: 2 | E19: 2 | F19: 2024-04-01 | G19: 2024-06-28 | H19: =INDEX(Stock_Prices!$G$2:$G$7501,MATCH("3_2024-04-01",Stock_Prices!$K$2:$K$7501,0)) -> 107.36 | I19: =INDEX(Stock_Prices!$G$2:$G$7501,MATCH("3_2024-06-28",Stock_Prices!$K$2:$K$7501,0)) -> 92.46 | J19: =ROUND((I19-H19)/H19*100,2) -> -13.88
A20: 3 | B20: JNJ | C20: 2024 | D20: 3 | E20: 3 | F20: 2024-07-01 | G20: 2024-09-30 | H20: =INDEX(Stock_Prices!$G$2:$G$7501,MATCH("3_2024-07-01",Stock_Prices!$K$2:$K$7501,0)) -> 90.27 | I20: =INDEX(Stock_Prices!$G$2:$G$7501,MATCH("3_2024-09-30",Stock_Prices!$K$2:$K$7501,0)) -> 107.99 | J20: =ROUND((I20-H20)/H20*100,2) -> 19.63
A21: 3 | B21: JNJ | C21: 2024 | D21: 4 | E21: 4 | F21: 2024-10-01 | G21: 2024-12-31 | H21: =INDEX(Stock_Prices!$G$2:$G$7501,MATCH("3_2024-10-01",Stock_Prices!$K$2:$K$7501,0)) -> 107.08 | I21: =INDEX(Stock_Prices!$G$2:$G$7501,MATCH("3_2024-12-31",Stock_Prices!$K$2:$K$7501,0)) -> 143.1 | J21: =ROUND((I21-H21)/H21*100,2) -> 33.64
A22: 3 | B22: JNJ | C22: 2025 | D22: 1 | E22: 5 | F22: 2025-01-01 | G22: 2025-03-31 | H22: =INDEX(Stock_Prices!$G$2:$G$7501,MATCH("3_2025-01-01",Stock_Prices!$K$2:$K$7501,0)) -> 140.87 | I22: =INDEX(Stock_Prices!$G$2:$G$7501,MATCH("3_2025-03-31",Stock_Prices!$K$2:$K$7501,0)) -> 145.48 | J22: =ROUND((I22-H22)/H22*100,2) -> 3.27
A23: 3 | B23: JNJ | C23: 2025 | D23: 2 | E23: 6 | F23: 2025-04-01 | G23: 2025-06-30 | H23: =INDEX(Stock_Prices!$G$2:$G$7501,MATCH("3_2025-04-01",Stock_Prices!$K$2:$K$7501,0)) -> 149.28 | I23: =INDEX(Stock_Prices!$G$2:$G$7501,MATCH("3_2025-06-30",Stock_Prices!$K$2:$K$7501,0)) -> 158.69 | J23: =ROUND((I23-H23)/H23*100,2) -> 6.3
A24: 3 | B24: JNJ | C24: 2025 | D24: 3 | E24: 7 | F24: 2025-07-01 | G24: 2025-09-30 | H24: =INDEX(Stock_Prices!$G$2:$G$7501,MATCH("3_2025-07-01",Stock_Prices!$K$2:$K$7501,0)) -> 156.92 | I24: =INDEX(Stock_Prices!$G$2:$G$7501,MATCH("3_2025-09-30",Stock_Prices!$K$2:$K$7501,0)) -> 175.43 | J24: =ROUND((I24-H24)/H24*100,2) -> 11.8
A25: 3 | B25: JNJ | C25: 2025 | D25: 4 | E25: 8 | F25: 2025-10-01 | G25: 2025-12-01 | H25: =INDEX(Stock_Prices!$G$2:$G$7501,MATCH("3_2025-10-01",Stock_Prices!$K$2:$K$7501,0)) -> 175.84 | I25: =INDEX(Stock_Prices!$G$2:$G$7501,MATCH("3_2025-12-01",Stock_Prices!$K$2:$K$7501,0)) -> 202.59 | J25: =ROUND((I25-H25)/H25*100,2) -> 15.21
A26: 4 | B26: PFE | C26: 2024 | D26: 1 | E26: 1 | F26: 2024-01-02 | G26: 2024-03-29 | H26: =INDEX(Stock_Prices!$G$2:$G$7501,MATCH("4_2024-01-02",Stock_Prices!$K$2:$K$7501,0)) -> 122.37 | I26: =INDEX(Stock_Prices!$G$2:$G$7501,MATCH("4_2024-03-29",Stock_Prices!$K$2:$K$7501,0)) -> 106.12 | J26: =ROUND((I26-H26)/H26*100,2) -> -13.28
A27: 4 | B27: PFE | C27: 2024 | D27: 2 | E27: 2 | F27: 2024-04-01 | G27: 2024-06-28 | H27: =INDEX(Stock_Prices!$G$2:$G$7501,MATCH("4_2024-04-01",Stock_Prices!$K$2:$K$7501,0)) -> 100.89 | I27: =INDEX(Stock_Prices!$G$2:$G$7501,MATCH("4_2024-06-28",Stock_Prices!$K$2:$K$7501,0)) -> 104.17 | J27: =ROUND((I27-H27)/H27*100,2) -> 3.25
A28: 4 | B28: PFE | C28: 2024 | D28: 3 | E28: 3 | F28: 2024-07-01 | G28: 2024-09-30 | H28: =INDEX(Stock_Prices!$G$2:$G$7501,MATCH("4_2024-07-01",Stock_Prices!$K$2:$K$7501,0)) -> 104.86 | I28: =INDEX(Stock_Prices!$G$2:$G$7501,MATCH("4_2024-09-30",Stock_Prices!$K$2:$K$7501,0)) -> 99.95 | J28: =ROUND((I28-H28)/H28*100,2) -> -4.68
A29: 4 | B29: PFE | C29: 2024 | D29: 4 | E29: 4 | F29: 2024-10-01 | G29: 2024-12-31 | H29: =INDEX(Stock_Prices!$G$2:$G$7501,MATCH("4_2024-10-01",Stock_Prices!$K$2:$K$7501,0)) -> 98.54 | I29: =INDEX(Stock_Prices!$G$2:$G$7501,MATCH("4_2024-12-31",Stock_Prices!$K$2:$K$7501,0)) -> 116.54 | J29: =ROUND((I29-H29)/H29*100,2) -> 18.27
A30: 4 | B30: PFE | C30: 2025 | D30: 1 | E30: 5 | F30: 2025-01-01 | G30: 2025-03-31 | H30: =INDEX(Stock_Prices!$G$2:$G$7501,MATCH("4_2025-01-01",Stock_Prices!$K$2:$K$7501,0)) -> 114.38 | I30: =INDEX(Stock_Prices!$G$2:$G$7501,MATCH("4_2025-03-31",Stock_Prices!$K$2:$K$7501,0)) -> 110.03 | J30: =ROUND((I30-H30)/H30*100,2) -> -3.8
A31: 4 | B31: PFE | C31: 2025 | D31: 2 | E31: 6 | F31: 2025-04-01 | G31: 2025-06-30 | H31: =INDEX(Stock_Prices!$G$2:$G$7501,MATCH("4_2025-04-01",Stock_Prices!$K$2:$K$7501,0)) -> 108.93 | I31: =INDEX(Stock_Prices!$G$2:$G$7501,MATCH("4_2025-06-30",Stock_Prices!$K$2:$K$7501,0)) -> 117.32 | J31: =ROUND((I31-H31)/H31*100,2) -> 7.7
A32: 4 | B32: PFE | C32: 2025 | D32: 3 | E32: 7 | F32: 2025-07-01 | G32: 2025-09-30 | H32: =INDEX(Stock_Prices!$G$2:$G$7501,MATCH("4_2025-07-01",Stock_Prices!$K$2:$K$7501,0)) -> 115.25 | I32: =INDEX(Stock_Prices!$G$2:$G$7501,MATCH("4_2025-09-30",Stock_Prices!$K$2:$K$7501,0)) -> 110.55 | J32: =ROUND((I32-H32)/H32*100,2) -> -4.08
A33: 4 | B33: PFE | C33: 2025 | D33: 4 | E33: 8 | F33: 2025-10-01 | G33: 2025-12-01 | H33: =INDEX(Stock_Prices!$G$2:$G$7501,MATCH("4_2025-10-01",Stock_Prices!$K$2:$K$7501,0)) -> 111.03 | I33: =INDEX(Stock_Prices!$G$2:$G$7501,MATCH("4_2025-12-01",Stock_Prices!$K$2:$K$7501,0)) -> 125.24 | J33: =ROUND((I33-H33)/H33*100,2) -> 12.8
A34: 5 | B34: JPM | C34: 2024 | D34: 1 | E34: 1 | F34: 2024-01-02 | G34: 2024-03-29 | H34: =INDEX(Stock_Prices!$G$2:$G$7501,MATCH("5_2024-01-02",Stock_Prices!$K$2:$K$7501,0)) -> 306.4 | I34: =INDEX(Stock_Prices!$G$2:$G$7501,MATCH("5_2024-03-29",Stock_Prices!$K$2:$K$7501,0)) -> 371.51 | J34: =ROUND((I34-H34)/H34*100,2) -> 21.25
A35: 5 | B35: JPM | C35: 2024 | D35: 2 | E35: 2 | F35: 2024-04-01 | G35: 2024-06-28 | H35: =INDEX(Stock_Prices!$G$2:$G$7501,MATCH("5_2024-04-01",Stock_Prices!$K$2:$K$7501,0)) -> 378.8 | I35: =INDEX(Stock_Prices!$G$2:$G$7501,MATCH("5_2024-06-28",Stock_Prices!$K$2:$K$7501,0)) -> 435.54 | J35: =ROUND((I35-H35)/H35*100,2) -> 14.98
A36: 5 | B36: JPM | C36: 2024 | D36: 3 | E36: 3 | F36: 2024-07-01 | G36: 2024-09-30 | H36: =INDEX(Stock_Prices!$G$2:$G$7501,MATCH("5_2024-07-01",Stock_Prices!$K$2:$K$7501,0)) -> 427.6 | I36: =INDEX(Stock_Prices!$G$2:$G$7501,MATCH("5_2024-09-30",Stock_Prices!$K$2:$K$7501,0)) -> 481.53 | J36: =ROUND((I36-H36)/H36*100,2) -> 12.61
A37: 5 | B37: JPM | C37: 2024 | D37: 4 | E37: 4 | F37: 2024-10-01 | G37: 2024-12-31 | H37: =INDEX(Stock_Prices!$G$2:$G$7501,MATCH("5_2024-10-01",Stock_Prices!$K$2:$K$7501,0)) -> 469.05 | I37: =INDEX(Stock_Prices!$G$2:$G$7501,MATCH("5_2024-12-31",Stock_Prices!$K$2:$K$7501,0)) -> 493.53 | J37: =ROUND((I37-H37)/H37*100,2) -> 5.22
A38: 5 | B38: JPM | C38: 2025 | D38: 1 | E38: 5 | F38: 2025-01-01 | G38: 2025-03-31 | H38: =INDEX(Stock_Prices!$G$2:$G$7501,MATCH("5_2025-01-01",Stock_Prices!$K$2:$K$7501,0)) -> 494.12 | I38: =INDEX(Stock_Prices!$G$2:$G$7501,MATCH("5_2025-03-31",Stock_Prices!$K$2:$K$7501,0)) -> 597.35 | J38: =ROUND((I38-H38)/H38*100,2) -> 20.89
A39: 5 | B39: JPM | C39: 2025 | D39: 2 | E39: 6 | F39: 2025-04-01 | G39: 2025-06-30 | H39: =INDEX(Stock_Prices!$G$2:$G$7501,MATCH("5_2025-04-01",Stock_Prices!$K$2:$K$7501,0)) -> 601.81 | I39: =INDEX(Stock_Prices!$G$2:$G$7501,MATCH("5_2025-06-30",Stock_Prices!$K$2:$K$7501,0)) -> 739.25 | J39: =ROUND((I39-H39)/H39*100,2) -> 22.84
A40: 5 | B40: JPM | C40: 2025 | D40: 3 | E40: 7 | F40: 2025-07-01 | G40: 2025-09-30 | H40: =INDEX(Stock_Prices!$G$2:$G$7501,MATCH("5_2025-07-01",Stock_Prices!$K$2:$K$7501,0)) -> 739.44 | I40: =INDEX(Stock_Prices!$G$2:$G$7501,MATCH("5_2025-09-30",Stock_Prices!$K$2:$K$7501,0)) -> 634.34 | J40: =ROUND((I40-H40)/H40*100,2) -> -14.21
...

Sheet Regression_Forecast_Analysis
A1: Quarterly Return Forecast — Linear Regression per Company
A2: Method: fit a linear trend (Excel SLOPE/INTERCEPT) on each company's quarterly returns for quarters 1–7, forecast quarter 8, and compare the forecast direction (up/down) against the actual result.
A4: company_id | B4: ticker | C4: slope | D4: intercept | E4: r_squared | F4: forecast_q8_return_pct | G4: actual_q8_return_pct | H4: forecast_direction | I4: actual_direction | J4: direction_match
A5: 1 | B5: AAPL | C5: =SLOPE(Quarterly_Returns!$J$2:$J$8,Quarterly_Returns!$E$2:$E$8) -> -6.7303571 | D5: =INTERCEPT(Quarterly_Returns!$J$2:$J$8,Quarterly_Returns!$E$2:$E$8) -> 30.8 | E5: =RSQ(Quarterly_Returns!$J$2:$J$8,Quarterly_Returns!$E$2:$E$8) -> 0.5050119 | F5: =ROUND(D5+C5*Quarterly_Returns!$E$9,2) -> -23.04 | G5: =ROUND(Quarterly_Returns!$J$9,2) -> 0.92 | H5: =IF(F5>=0,"Up","Down") -> Down | I5: =IF(G5>=0,"Up","Down") -> Up | J5: =IF(H5=I5,1,0) -> 0
A6: 2 | B6: MSFT | C6: =SLOPE(Quarterly_Returns!$J$10:$J$16,Quarterly_Returns!$E$10:$E$16) -> -3.9571429 | D6: =INTERCEPT(Quarterly_Returns!$J$10:$J$16,Quarterly_Returns!$E$10:$E$16) -> 10.731429 | E6: =RSQ(Quarterly_Returns!$J$10:$J$16,Quarterly_Returns!$E$10:$E$16) -> 0.22756866 | F6: =ROUND(D6+C6*Quarterly_Returns!$E$17,2) -> -20.93 | G6: =ROUND(Quarterly_Returns!$J$17,2) -> -16.1 | H6: =IF(F6>=0,"Up","Down") -> Down | I6: =IF(G6>=0,"Up","Down") -> Down | J6: =IF(H6=I6,1,0) -> 1
A7: 3 | B7: JNJ | C7: =SLOPE(Quarterly_Returns!$J$18:$J$24,Quarterly_Returns!$E$18:$E$24) -> 4.3317857 | D7: =INTERCEPT(Quarterly_Returns!$J$18:$J$24,Quarterly_Returns!$E$18:$E$24) -> -11.594286 | E7: =RSQ(Quarterly_Returns!$J$18:$J$24,Quarterly_Returns!$E$18:$E$24) -> 0.25081249 | F7: =ROUND(D7+C7*Quarterly_Returns!$E$25,2) -> 23.06 | G7: =ROUND(Quarterly_Returns!$J$25,2) -> 15.21 | H7: =IF(F7>=0,"Up","Down") -> Up | I7: =IF(G7>=0,"Up","Down") -> Up | J7: =IF(H7=I7,1,0) -> 1
A8: 4 | B8: PFE | C8: =SLOPE(Quarterly_Returns!$J$26:$J$32,Quarterly_Returns!$E$26:$E$32) -> 1.335 | D8: =INTERCEPT(Quarterly_Returns!$J$26:$J$32,Quarterly_Returns!$E$26:$E$32) -> -4.8571429 | E8: =RSQ(Quarterly_Returns!$J$26:$J$32,Quarterly_Returns!$E$26:$E$32) -> 0.079039307 | F8: =ROUND(D8+C8*Quarterly_Returns!$E$33,2) -> 5.82 | G8: =ROUND(Quarterly_Returns!$J$33,2) -> 12.8 | H8: =IF(F8>=0,"Up","Down") -> Up | I8: =IF(G8>=0,"Up","Down") -> Up | J8: =IF(H8=I8,1,0) -> 1
A9: 5 | B9: JPM | C9: =SLOPE(Quarterly_Returns!$J$34:$J$40,Quarterly_Returns!$E$34:$E$40) -> -2.9421429 | D9: =INTERCEPT(Quarterly_Returns!$J$34:$J$40,Quarterly_Returns!$E$34:$E$40) -> 23.708571 | E9: =RSQ(Quarterly_Returns!$J$34:$J$40,Quarterly_Returns!$E$34:$E$40) -> 0.23663301 | F9: =ROUND(D9+C9*Quarterly_Returns!$E$41,2) -> 0.17 | G9: =ROUND(Quarterly_Returns!$J$41,2) -> 14.7 | H9: =IF(F9>=0,"Up","Down") -> Up | I9: =IF(G9>=0,"Up","Down") -> Up | J9: =IF(H9=I9,1,0) -> 1
A10: 6 | B10: GS | C10: =SLOPE(Quarterly_Returns!$J$42:$J$48,Quarterly_Returns!$E$42:$E$48) -> 2.025 | D10: =INTERCEPT(Quarterly_Returns!$J$42:$J$48,Quarterly_Returns!$E$42:$E$48) -> -7.5671429 | E10: =RSQ(Quarterly_Returns!$J$42:$J$48,Quarterly_Returns!$E$42:$E$48) -> 0.079159406 | F10: =ROUND(D10+C10*Quarterly_Returns!$E$49,2) -> 8.63 | G10: =ROUND(Quarterly_Returns!$J$49,2) -> 9.99 | H10: =IF(F10>=0,"Up","Down") -> Up | I10: =IF(G10>=0,"Up","Down") -> Up | J10: =IF(H10=I10,1,0) -> 1
A11: 7 | B11: XOM | C11: =SLOPE(Quarterly_Returns!$J$50:$J$56,Quarterly_Returns!$E$50:$E$56) -> -3.0832143 | D11: =INTERCEPT(Quarterly_Returns!$J$50:$J$56,Quarterly_Returns!$E$50:$E$56) -> 9.8071429 | E11: =RSQ(Quarterly_Returns!$J$50:$J$56,Quarterly_Returns!$E$50:$E$56) -> 0.13365663 | F11: =ROUND(D11+C11*Quarterly_Returns!$E$57,2) -> -14.86 | G11: =ROUND(Quarterly_Returns!$J$57,2) -> 4.17 | H11: =IF(F11>=0,"Up","Down") -> Down | I11: =IF(G11>=0,"Up","Down") -> Up | J11: =IF(H11=I11,1,0) -> 0
A12: 8 | B12: CVX | C12: =SLOPE(Quarterly_Returns!$J$58:$J$64,Quarterly_Returns!$E$58:$E$64) -> 6.0464286 | D12: =INTERCEPT(Quarterly_Returns!$J$58:$J$64,Quarterly_Returns!$E$58:$E$64) -> -21.477143 | E12: =RSQ(Quarterly_Returns!$J$58:$J$64,Quarterly_Returns!$E$58:$E$64) -> 0.72302953 | F12: =ROUND(D12+C12*Quarterly_Returns!$E$65,2) -> 26.89 | G12: =ROUND(Quarterly_Returns!$J$65,2) -> 5.21 | H12: =IF(F12>=0,"Up","Down") -> Up | I12: =IF(G12>=0,"Up","Down") -> Up | J12: =IF(H12=I12,1,0) -> 1
A13: 9 | B13: PG | C13: =SLOPE(Quarterly_Returns!$J$66:$J$72,Quarterly_Returns!$E$66:$E$72) -> -0.9875 | D13: =INTERCEPT(Quarterly_Returns!$J$66:$J$72,Quarterly_Returns!$E$66:$E$72) -> 8.7542857 | E13: =RSQ(Quarterly_Returns!$J$66:$J$72,Quarterly_Returns!$E$66:$E$72) -> 0.017336957 | F13: =ROUND(D13+C13*Quarterly_Returns!$E$73,2) -> 0.85 | G13: =ROUND(Quarterly_Returns!$J$73,2) -> 29.52 | H13: =IF(F13>=0,"Up","Down") -> Up | I13: =IF(G13>=0,"Up","Down") -> Up | J13: =IF(H13=I13,1,0) -> 1
A14: 10 | B14: KO | C14: =SLOPE(Quarterly_Returns!$J$74:$J$80,Quarterly_Returns!$E$74:$E$80) -> 3.9482143 | D14: =INTERCEPT(Quarterly_Returns!$J$74:$J$80,Quarterly_Returns!$E$74:$E$80) -> -3.9985714 | E14: =RSQ(Quarterly_Returns!$J$74:$J$80,Quarterly_Returns!$E$74:$E$80) -> 0.25977503 | F14: =ROUND(D14+C14*Quarterly_Returns!$E$81,2) -> 27.59 | G14: =ROUND(Quarterly_Returns!$J$81,2) -> 2.81 | H14: =IF(F14>=0,"Up","Down") -> Up | I14: =IF(G14>=0,"Up","Down") -> Up | J14: =IF(H14=I14,1,0) -> 1
A15: 11 | B15: SPY | C15: =SLOPE(Quarterly_Returns!$J$82:$J$88,Quarterly_Returns!$E$82:$E$88) -> 0.44107143 | D15: =INTERCEPT(Quarterly_Returns!$J$82:$J$88,Quarterly_Returns!$E$82:$E$88) -> -3.5471429 | E15: =RSQ(Quarterly_Returns!$J$82:$J$88,Quarterly_Returns!$E$82:$E$88) -> 0.0092398173 | F15: =ROUND(D15+C15*Quarterly_Returns!$E$89,2) -> -0.02 | G15: =ROUND(Quarterly_Returns!$J$89,2) -> -8.2 | H15: =IF(F15>=0,"Up","Down") -> Down | I15: =IF(G15>=0,"Up","Down") -> Down | J15: =IF(H15=I15,1,0) -> 1
A16: 12 | B16: AGG | C16: =SLOPE(Quarterly_Returns!$J$90:$J$96,Quarterly_Returns!$E$90:$E$96) -> -0.59571429 | D16: =INTERCEPT(Quarterly_Returns!$J$90:$J$96,Quarterly_Returns!$E$90:$E$96) -> 1.8371429 | E16: =RSQ(Quarterly_Returns!$J$90:$J$96,Quarterly_Returns!$E$90:$E$96) -> 0.17400924 | F16: =ROUND(D16+C16*Quarterly_Returns!$E$97,2) -> -2.93 | G16: =ROUND(Quarterly_Returns!$J$97,2) -> -0.16 | H16: =IF(F16>=0,"Up","Down") -> Down | I16: =IF(G16>=0,"Up","Down") -> Down | J16: =IF(H16=I16,1,0) -> 1
A17: 13 | B17: GLD | C17: =SLOPE(Quarterly_Returns!$J$98:$J$104,Quarterly_Returns!$E$98:$E$104) -> 1.7035714 | D17: =INTERCEPT(Quarterly_Returns!$J$98:$J$104,Quarterly_Returns!$E$98:$E$104) -> -5.9657143 | E17: =RSQ(Quarterly_Returns!$J$98:$J$104,Quarterly_Returns!$E$98:$E$104) -> 0.033819031 | F17: =ROUND(D17+C17*Quarterly_Returns!$E$105,2) -> 7.66 | G17: =ROUND(Quarterly_Returns!$J$105,2) -> 8.64 | H17: =IF(F17>=0,"Up","Down") -> Up | I17: =IF(G17>=0,"Up","Down") -> Up | J17: =IF(H17=I17,1,0) -> 1
A18: 14 | B18: USO | C18: =SLOPE(Quarterly_Returns!$J$106:$J$112,Quarterly_Returns!$E$106:$E$112) -> 1.6289286 | D18: =INTERCEPT(Quarterly_Returns!$J$106:$J$112,Quarterly_Returns!$E$106:$E$112) -> -15.381429 | E18: =RSQ(Quarterly_Returns!$J$106:$J$112,Quarterly_Returns!$E$106:$E$112) -> 0.1248981 | F18: =ROUND(D18+C18*Quarterly_Returns!$E$113,2) -> -2.35 | G18: =ROUND(Quarterly_Returns!$J$113,2) -> -15.86 | H18: =IF(F18>=0,"Up","Down") -> Down | I18: =IF(G18>=0,"Up","Down") -> Down | J18: =IF(H18=I18,1,0) -> 1
A19: 15 | B19: UUP | C19: =SLOPE(Quarterly_Returns!$J$114:$J$120,Quarterly_Returns!$E$114:$E$120) -> -0.095357143 | D19: =INTERCEPT(Quarterly_Returns!$J$114:$J$120,Quarterly_Returns!$E$114:$E$120) -> 0.87428571 | E19: =RSQ(Quarterly_Returns!$J$114:$J$120,Quarterly_Returns!$E$114:$E$120) -> 0.0014767885 | F19: =ROUND(D19+C19*Quarterly_Returns!$E$121,2) -> 0.11 | G19: =ROUND(Quarterly_Returns!$J$121,2) -> 6.14 | H19: =IF(F19>=0,"Up","Down") -> Up | I19: =IF(G19>=0,"Up","Down") -> Up | J19: =IF(H19=I19,1,0) -> 1
A21: Overall Directional Forecast Accuracy: | F21: =ROUND(AVERAGE(J5:J19)*100,1)&"%" -> 86.7%
A23: Note: accuracy = % of companies where the forecast direction (gain vs loss) matched the actual quarter's direction. Adjust the sample window or use R² as an alternate accuracy lens.

Sheet Sector_Correlation_Matrix
A1: Asset Class Correlation Matrix (based on quarterly returns)
A3: Avg Quarterly Return by Asset Class (%) — helper data
A4: quarter_index | B4: Bond | C4: Commodity | D4: Currency | E4: ETF | F4: Equity
A5: 1 | B5: =ROUND((AVERAGEIFS(Quarterly_Returns!$J$2:$J$121,Quarterly_Returns!$E$2:$E$121,$A5,Quarterly_Returns!$A$2:$A$121,12))/1,2) -> -0.83 | C5: =ROUND((AVERAGEIFS(Quarterly_Returns!$J$2:$J$121,Quarterly_Returns!$E$2:$E$121,$A5,Quarterly_Returns!$A$2:$A$121,13)+AVERAGEIFS(Quarterly_Returns!$J$2:$J$121,Quarterly_Returns!$E$2:$E$121,$A5,Quarterly_Returns!$A$2:$A$121,14))/2,2) -> -14.02 | D5: =ROUND((AVERAGEIFS(Quarterly_Returns!$J$2:$J$121,Quarterly_Returns!$E$2:$E$121,$A5,Quarterly_Returns!$A$2:$A$121,15))/1,2) -> 0.66 | E5: =ROUND((AVERAGEIFS(Quarterly_Returns!$J$2:$J$121,Quarterly_Returns!$E$2:$E$121,$A5,Quarterly_Returns!$A$2:$A$121,11))/1,2) -> 3.18 | F5: =ROUND((AVERAGEIFS(Quarterly_Returns!$J$2:$J$121,Quarterly_Returns!$E$2:$E$121,$A5,Quarterly_Returns!$A$2:$A$121,1)+AVERAGEIFS(Quarterly_Returns!$J$2:$J$121,Quarterly_Returns!$E$2:$E$121,$A5,Quarterly_Returns!$A$2:$A$121,2)+AVERAGEIFS(Quarterly_Returns!$J$2:$J$121,Quarterly_Returns!$E$2:$E$121,$A5,Quarterly_Returns!$A$2:$A$121,3)+AVERAGEIFS(Quarterly_Returns!$J$2:$J$121,Quarterly_Returns!$E$2:$E$121,$A5,Quarterly_Returns!$A$2:$A$121,4)+AVERAGEIFS(Quarterly_Returns!$J$2:$J$121,Quarterly_Returns!$E$2:$E$121,$A5,Quarterly_Returns!$A$2:$A$121,5)+AVERAGEIFS(Quarterly_Returns!$J$2:$J$121,Quarterly_Returns!$E$2:$E$121,$A5,Quarterly_Returns!$A$2:$A$121,6)+AVERAGEIFS(Quarterly_Returns!$J$2:$J$121,Quarterly_Returns!$E$2:$E$121,$A5,Quarterly_Returns!$A$2:$A$121,7)+AVERAGEIFS(Quarterly_Returns!$J$2:$J$121,Quarterly_Returns!$E$2:$E$121,$A5,Quarterly_Returns!$A$2:$A$121,8)+AVERAGEIFS(Quarterly_Returns!$J$2:$J$121,Quarterly_Returns!$E$2:$E$121,$A5,Quarterly_Returns!$A$2:$A$121,9)+AVERAGEIFS(Quarterly_Returns!$J$2:$J$121,Quarterly_Returns!$E$2:$E$121,$A5,Quarterly_Returns!$A$2:$A$121,10))/10,2) -> 6.4
A6: 2 | B6: =ROUND((AVERAGEIFS(Quarterly_Returns!$J$2:$J$121,Quarterly_Returns!$E$2:$E$121,$A6,Quarterly_Returns!$A$2:$A$121,12))/1,2) -> -0.41 | C6: =ROUND((AVERAGEIFS(Quarterly_Returns!$J$2:$J$121,Quarterly_Returns!$E$2:$E$121,$A6,Quarterly_Returns!$A$2:$A$121,13)+AVERAGEIFS(Quarterly_Returns!$J$2:$J$121,Quarterly_Returns!$E$2:$E$121,$A6,Quarterly_Returns!$A$2:$A$121,14))/2,2) -> -4.33 | D6: =ROUND((AVERAGEIFS(Quarterly_Returns!$J$2:$J$121,Quarterly_Returns!$E$2:$E$121,$A6,Quarterly_Returns!$A$2:$A$121,15))/1,2) -> -1.27 | E6: =ROUND((AVERAGEIFS(Quarterly_Returns!$J$2:$J$121,Quarterly_Returns!$E$2:$E$121,$A6,Quarterly_Returns!$A$2:$A$121,11))/1,2) -> -13.65 | F6: =ROUND((AVERAGEIFS(Quarterly_Returns!$J$2:$J$121,Quarterly_Returns!$E$2:$E$121,$A6,Quarterly_Returns!$A$2:$A$121,1)+AVERAGEIFS(Quarterly_Returns!$J$2:$J$121,Quarterly_Returns!$E$2:$E$121,$A6,Quarterly_Returns!$A$2:$A$121,2)+AVERAGEIFS(Quarterly_Returns!$J$2:$J$121,Quarterly_Returns!$E$2:$E$121,$A6,Quarterly_Returns!$A$2:$A$121,3)+AVERAGEIFS(Quarterly_Returns!$J$2:$J$121,Quarterly_Returns!$E$2:$E$121,$A6,Quarterly_Returns!$A$2:$A$121,4)+AVERAGEIFS(Quarterly_Returns!$J$2:$J$121,Quarterly_Returns!$E$2:$E$121,$A6,Quarterly_Returns!$A$2:$A$121,5)+AVERAGEIFS(Quarterly_Returns!$J$2:$J$121,Quarterly_Returns!$E$2:$E$121,$A6,Quarterly_Returns!$A$2:$A$121,6)+AVERAGEIFS(Quarterly_Returns!$J$2:$J$121,Quarterly_Returns!$E$2:$E$121,$A6,Quarterly_Returns!$A$2:$A$121,7)+AVERAGEIFS(Quarterly_Returns!$J$2:$J$121,Quarterly_Returns!$E$2:$E$121,$A6,Quarterly_Returns!$A$2:$A$121,8)+AVERAGEIFS(Quarterly_Returns!$J$2:$J$121,Quarterly_Returns!$E$2:$E$121,$A6,Quarterly_Returns!$A$2:$A$121,9)+AVERAGEIFS(Quarterly_Returns!$J$2:$J$121,Quarterly_Returns!$E$2:$E$121,$A6,Quarterly_Returns!$A$2:$A$121,10))/10,2) -> 1.45
A7: 3 | B7: =ROUND((AVERAGEIFS(Quarterly_Returns!$J$2:$J$121,Quarterly_Returns!$E$2:$E$121,$A7,Quarterly_Returns!$A$2:$A$121,12))/1,2) -> 1.36 | C7: =ROUND((AVERAGEIFS(Quarterly_Returns!$J$2:$J$121,Quarterly_Returns!$E$2:$E$121,$A7,Quarterly_Returns!$A$2:$A$121,13)+AVERAGEIFS(Quarterly_Returns!$J$2:$J$121,Quarterly_Returns!$E$2:$E$121,$A7,Quarterly_Returns!$A$2:$A$121,14))/2,2) -> -0.52 | D7: =ROUND((AVERAGEIFS(Quarterly_Returns!$J$2:$J$121,Quarterly_Returns!$E$2:$E$121,$A7,Quarterly_Returns!$A$2:$A$121,15))/1,2) -> -4.25 | E7: =ROUND((AVERAGEIFS(Quarterly_Returns!$J$2:$J$121,Quarterly_Returns!$E$2:$E$121,$A7,Quarterly_Returns!$A$2:$A$121,11))/1,2) -> -4.74 | F7: =ROUND((AVERAGEIFS(Quarterly_Returns!$J$2:$J$121,Quarterly_Returns!$E$2:$E$121,$A7,Quarterly_Returns!$A$2:$A$121,1)+AVERAGEIFS(Quarterly_Returns!$J$2:$J$121,Quarterly_Returns!$E$2:$E$121,$A7,Quarterly_Returns!$A$2:$A$121,2)+AVERAGEIFS(Quarterly_Returns!$J$2:$J$121,Quarterly_Returns!$E$2:$E$121,$A7,Quarterly_Returns!$A$2:$A$121,3)+AVERAGEIFS(Quarterly_Returns!$J$2:$J$121,Quarterly_Returns!$E$2:$E$121,$A7,Quarterly_Returns!$A$2:$A$121,4)+AVERAGEIFS(Quarterly_Returns!$J$2:$J$121,Quarterly_Returns!$E$2:$E$121,$A7,Quarterly_Returns!$A$2:$A$121,5)+AVERAGEIFS(Quarterly_Returns!$J$2:$J$121,Quarterly_Returns!$E$2:$E$121,$A7,Quarterly_Returns!$A$2:$A$121,6)+AVERAGEIFS(Quarterly_Returns!$J$2:$J$121,Quarterly_Returns!$E$2:$E$121,$A7,Quarterly_Returns!$A$2:$A$121,7)+AVERAGEIFS(Quarterly_Returns!$J$2:$J$121,Quarterly_Returns!$E$2:$E$121,$A7,Quarterly_Returns!$A$2:$A$121,8)+AVERAGEIFS(Quarterly_Returns!$J$2:$J$121,Quarterly_Returns!$E$2:$E$121,$A7,Quarterly_Returns!$A$2:$A$121,9)+AVERAGEIFS(Quarterly_Returns!$J$2:$J$121,Quarterly_Returns!$E$2:$E$121,$A7,Quarterly_Returns!$A$2:$A$121,10))/10,2) -> -0.29
A8: 4 | B8: =ROUND((AVERAGEIFS(Quarterly_Returns!$J$2:$J$121,Quarterly_Returns!$E$2:$E$121,$A8,Quarterly_Returns!$A$2:$A$121,12))/1,2) -> 5.18 | C8: =ROUND((AVERAGEIFS(Quarterly_Returns!$J$2:$J$121,Quarterly_Returns!$E$2:$E$121,$A8,Quarterly_Returns!$A$2:$A$121,13)+AVERAGEIFS(Quarterly_Returns!$J$2:$J$121,Quarterly_Returns!$E$2:$E$121,$A8,Quarterly_Returns!$A$2:$A$121,14))/2,2) -> 0.53 | D8: =ROUND((AVERAGEIFS(Quarterly_Returns!$J$2:$J$121,Quarterly_Returns!$E$2:$E$121,$A8,Quarterly_Returns!$A$2:$A$121,15))/1,2) -> 12.18 | E8: =ROUND((AVERAGEIFS(Quarterly_Returns!$J$2:$J$121,Quarterly_Returns!$E$2:$E$121,$A8,Quarterly_Returns!$A$2:$A$121,11))/1,2) -> -2.1 | F8: =ROUND((AVERAGEIFS(Quarterly_Returns!$J$2:$J$121,Quarterly_Returns!$E$2:$E$121,$A8,Quarterly_Returns!$A$2:$A$121,1)+AVERAGEIFS(Quarterly_Returns!$J$2:$J$121,Quarterly_Returns!$E$2:$E$121,$A8,Quarterly_Returns!$A$2:$A$121,2)+AVERAGEIFS(Quarterly_Returns!$J$2:$J$121,Quarterly_Returns!$E$2:$E$121,$A8,Quarterly_Returns!$A$2:$A$121,3)+AVERAGEIFS(Quarterly_Returns!$J$2:$J$121,Quarterly_Returns!$E$2:$E$121,$A8,Quarterly_Returns!$A$2:$A$121,4)+AVERAGEIFS(Quarterly_Returns!$J$2:$J$121,Quarterly_Returns!$E$2:$E$121,$A8,Quarterly_Returns!$A$2:$A$121,5)+AVERAGEIFS(Quarterly_Returns!$J$2:$J$121,Quarterly_Returns!$E$2:$E$121,$A8,Quarterly_Returns!$A$2:$A$121,6)+AVERAGEIFS(Quarterly_Returns!$J$2:$J$121,Quarterly_Returns!$E$2:$E$121,$A8,Quarterly_Returns!$A$2:$A$121,7)+AVERAGEIFS(Quarterly_Returns!$J$2:$J$121,Quarterly_Returns!$E$2:$E$121,$A8,Quarterly_Returns!$A$2:$A$121,8)+AVERAGEIFS(Quarterly_Returns!$J$2:$J$121,Quarterly_Returns!$E$2:$E$121,$A8,Quarterly_Returns!$A$2:$A$121,9)+AVERAGEIFS(Quarterly_Returns!$J$2:$J$121,Quarterly_Returns!$E$2:$E$121,$A8,Quarterly_Returns!$A$2:$A$121,10))/10,2) -> 4.62
A9: 5 | B9: =ROUND((AVERAGEIFS(Quarterly_Returns!$J$2:$J$121,Quarterly_Returns!$E$2:$E$121,$A9,Quarterly_Returns!$A$2:$A$121,12))/1,2) -> -3.4 | C9: =ROUND((AVERAGEIFS(Quarterly_Returns!$J$2:$J$121,Quarterly_Returns!$E$2:$E$121,$A9,Quarterly_Returns!$A$2:$A$121,13)+AVERAGEIFS(Quarterly_Returns!$J$2:$J$121,Quarterly_Returns!$E$2:$E$121,$A9,Quarterly_Returns!$A$2:$A$121,14))/2,2) -> -23.33 | D9: =ROUND((AVERAGEIFS(Quarterly_Returns!$J$2:$J$121,Quarterly_Returns!$E$2:$E$121,$A9,Quarterly_Returns!$A$2:$A$121,15))/1,2) -> -1.74 | E9: =ROUND((AVERAGEIFS(Quarterly_Returns!$J$2:$J$121,Quarterly_Returns!$E$2:$E$121,$A9,Quarterly_Returns!$A$2:$A$121,11))/1,2) -> 5.97 | F9: =ROUND((AVERAGEIFS(Quarterly_Returns!$J$2:$J$121,Quarterly_Returns!$E$2:$E$121,$A9,Quarterly_Returns!$A$2:$A$121,1)+AVERAGEIFS(Quarterly_Returns!$J$2:$J$121,Quarterly_Returns!$E$2:$E$121,$A9,Quarterly_Returns!$A$2:$A$121,2)+AVERAGEIFS(Quarterly_Returns!$J$2:$J$121,Quarterly_Returns!$E$2:$E$121,$A9,Quarterly_Returns!$A$2:$A$121,3)+AVERAGEIFS(Quarterly_Returns!$J$2:$J$121,Quarterly_Returns!$E$2:$E$121,$A9,Quarterly_Returns!$A$2:$A$121,4)+AVERAGEIFS(Quarterly_Returns!$J$2:$J$121,Quarterly_Returns!$E$2:$E$121,$A9,Quarterly_Returns!$A$2:$A$121,5)+AVERAGEIFS(Quarterly_Returns!$J$2:$J$121,Quarterly_Returns!$E$2:$E$121,$A9,Quarterly_Returns!$A$2:$A$121,6)+AVERAGEIFS(Quarterly_Returns!$J$2:$J$121,Quarterly_Returns!$E$2:$E$121,$A9,Quarterly_Returns!$A$2:$A$121,7)+AVERAGEIFS(Quarterly_Returns!$J$2:$J$121,Quarterly_Returns!$E$2:$E$121,$A9,Quarterly_Returns!$A$2:$A$121,8)+AVERAGEIFS(Quarterly_Returns!$J$2:$J$121,Quarterly_Returns!$E$2:$E$121,$A9,Quarterly_Returns!$A$2:$A$121,9)+AVERAGEIFS(Quarterly_Returns!$J$2:$J$121,Quarterly_Returns!$E$2:$E$121,$A9,Quarterly_Returns!$A$2:$A$121,10))/10,2) -> 3.58
A10: 6 | B10: =ROUND((AVERAGEIFS(Quarterly_Returns!$J$2:$J$121,Quarterly_Returns!$E$2:$E$121,$A10,Quarterly_Returns!$A$2:$A$121,12))/1,2) -> -1.93 | C10: =ROUND((AVERAGEIFS(Quarterly_Returns!$J$2:$J$121,Quarterly_Returns!$E$2:$E$121,$A10,Quarterly_Returns!$A$2:$A$121,13)+AVERAGEIFS(Quarterly_Returns!$J$2:$J$121,Quarterly_Returns!$E$2:$E$121,$A10,Quarterly_Returns!$A$2:$A$121,14))/2,2) -> 22 | D10: =ROUND((AVERAGEIFS(Quarterly_Returns!$J$2:$J$121,Quarterly_Returns!$E$2:$E$121,$A10,Quarterly_Returns!$A$2:$A$121,15))/1,2) -> -0.65 | E10: =ROUND((AVERAGEIFS(Quarterly_Returns!$J$2:$J$121,Quarterly_Returns!$E$2:$E$121,$A10,Quarterly_Returns!$A$2:$A$121,11))/1,2) -> 12.7 | F10: =ROUND((AVERAGEIFS(Quarterly_Returns!$J$2:$J$121,Quarterly_Returns!$E$2:$E$121,$A10,Quarterly_Returns!$A$2:$A$121,1)+AVERAGEIFS(Quarterly_Returns!$J$2:$J$121,Quarterly_Returns!$E$2:$E$121,$A10,Quarterly_Returns!$A$2:$A$121,2)+AVERAGEIFS(Quarterly_Returns!$J$2:$J$121,Quarterly_Returns!$E$2:$E$121,$A10,Quarterly_Returns!$A$2:$A$121,3)+AVERAGEIFS(Quarterly_Returns!$J$2:$J$121,Quarterly_Returns!$E$2:$E$121,$A10,Quarterly_Returns!$A$2:$A$121,4)+AVERAGEIFS(Quarterly_Returns!$J$2:$J$121,Quarterly_Returns!$E$2:$E$121,$A10,Quarterly_Returns!$A$2:$A$121,5)+AVERAGEIFS(Quarterly_Returns!$J$2:$J$121,Quarterly_Returns!$E$2:$E$121,$A10,Quarterly_Returns!$A$2:$A$121,6)+AVERAGEIFS(Quarterly_Returns!$J$2:$J$121,Quarterly_Returns!$E$2:$E$121,$A10,Quarterly_Returns!$A$2:$A$121,7)+AVERAGEIFS(Quarterly_Returns!$J$2:$J$121,Quarterly_Returns!$E$2:$E$121,$A10,Quarterly_Returns!$A$2:$A$121,8)+AVERAGEIFS(Quarterly_Returns!$J$2:$J$121,Quarterly_Returns!$E$2:$E$121,$A10,Quarterly_Returns!$A$2:$A$121,9)+AVERAGEIFS(Quarterly_Returns!$J$2:$J$121,Quarterly_Returns!$E$2:$E$121,$A10,Quarterly_Returns!$A$2:$A$121,10))/10,2) -> 6.4
A11: 7 | B11: =ROUND((AVERAGEIFS(Quarterly_Returns!$J$2:$J$121,Quarterly_Returns!$E$2:$E$121,$A11,Quarterly_Returns!$A$2:$A$121,12))/1,2) -> -3.79 | C11: =ROUND((AVERAGEIFS(Quarterly_Returns!$J$2:$J$121,Quarterly_Returns!$E$2:$E$121,$A11,Quarterly_Returns!$A$2:$A$121,13)+AVERAGEIFS(Quarterly_Returns!$J$2:$J$121,Quarterly_Returns!$E$2:$E$121,$A11,Quarterly_Returns!$A$2:$A$121,14))/2,2) -> -8.41 | D11: =ROUND((AVERAGEIFS(Quarterly_Returns!$J$2:$J$121,Quarterly_Returns!$E$2:$E$121,$A11,Quarterly_Returns!$A$2:$A$121,15))/1,2) -> -1.48 | E11: =ROUND((AVERAGEIFS(Quarterly_Returns!$J$2:$J$121,Quarterly_Returns!$E$2:$E$121,$A11,Quarterly_Returns!$A$2:$A$121,11))/1,2) -> -13.84 | F11: =ROUND((AVERAGEIFS(Quarterly_Returns!$J$2:$J$121,Quarterly_Returns!$E$2:$E$121,$A11,Quarterly_Returns!$A$2:$A$121,1)+AVERAGEIFS(Quarterly_Returns!$J$2:$J$121,Quarterly_Returns!$E$2:$E$121,$A11,Quarterly_Returns!$A$2:$A$121,2)+AVERAGEIFS(Quarterly_Returns!$J$2:$J$121,Quarterly_Returns!$E$2:$E$121,$A11,Quarterly_Returns!$A$2:$A$121,3)+AVERAGEIFS(Quarterly_Returns!$J$2:$J$121,Quarterly_Returns!$E$2:$E$121,$A11,Quarterly_Returns!$A$2:$A$121,4)+AVERAGEIFS(Quarterly_Returns!$J$2:$J$121,Quarterly_Returns!$E$2:$E$121,$A11,Quarterly_Returns!$A$2:$A$121,5)+AVERAGEIFS(Quarterly_Returns!$J$2:$J$121,Quarterly_Returns!$E$2:$E$121,$A11,Quarterly_Returns!$A$2:$A$121,6)+AVERAGEIFS(Quarterly_Returns!$J$2:$J$121,Quarterly_Returns!$E$2:$E$121,$A11,Quarterly_Returns!$A$2:$A$121,7)+AVERAGEIFS(Quarterly_Returns!$J$2:$J$121,Quarterly_Returns!$E$2:$E$121,$A11,Quarterly_Returns!$A$2:$A$121,8)+AVERAGEIFS(Quarterly_Returns!$J$2:$J$121,Quarterly_Returns!$E$2:$E$121,$A11,Quarterly_Returns!$A$2:$A$121,9)+AVERAGEIFS(Quarterly_Returns!$J$2:$J$121,Quarterly_Returns!$E$2:$E$121,$A11,Quarterly_Returns!$A$2:$A$121,10))/10,2) -> 1.81
A12: 8 | B12: =ROUND((AVERAGEIFS(Quarterly_Returns!$J$2:$J$121,Quarterly_Returns!$E$2:$E$121,$A12,Quarterly_Returns!$A$2:$A$121,12))/1,2) -> -0.16 | C12: =ROUND((AVERAGEIFS(Quarterly_Returns!$J$2:$J$121,Quarterly_Returns!$E$2:$E$121,$A12,Quarterly_Returns!$A$2:$A$121,13)+AVERAGEIFS(Quarterly_Returns!$J$2:$J$121,Quarterly_Returns!$E$2:$E$121,$A12,Quarterly_Returns!$A$2:$A$121,14))/2,2) -> -3.61 | D12: =ROUND((AVERAGEIFS(Quarterly_Returns!$J$2:$J$121,Quarterly_Returns!$E$2:$E$121,$A12,Quarterly_Returns!$A$2:$A$121,15))/1,2) -> 6.14 | E12: =ROUND((AVERAGEIFS(Quarterly_Returns!$J$2:$J$121,Quarterly_Returns!$E$2:$E$121,$A12,Quarterly_Returns!$A$2:$A$121,11))/1,2) -> -8.2 | F12: =ROUND((AVERAGEIFS(Quarterly_Returns!$J$2:$J$121,Quarterly_Returns!$E$2:$E$121,$A12,Quarterly_Returns!$A$2:$A$121,1)+AVERAGEIFS(Quarterly_Returns!$J$2:$J$121,Quarterly_Returns!$E$2:$E$121,$A12,Quarterly_Returns!$A$2:$A$121,2)+AVERAGEIFS(Quarterly_Returns!$J$2:$J$121,Quarterly_Returns!$E$2:$E$121,$A12,Quarterly_Returns!$A$2:$A$121,3)+AVERAGEIFS(Quarterly_Returns!$J$2:$J$121,Quarterly_Returns!$E$2:$E$121,$A12,Quarterly_Returns!$A$2:$A$121,4)+AVERAGEIFS(Quarterly_Returns!$J$2:$J$121,Quarterly_Returns!$E$2:$E$121,$A12,Quarterly_Returns!$A$2:$A$121,5)+AVERAGEIFS(Quarterly_Returns!$J$2:$J$121,Quarterly_Returns!$E$2:$E$121,$A12,Quarterly_Returns!$A$2:$A$121,6)+AVERAGEIFS(Quarterly_Returns!$J$2:$J$121,Quarterly_Returns!$E$2:$E$121,$A12,Quarterly_Returns!$A$2:$A$121,7)+AVERAGEIFS(Quarterly_Returns!$J$2:$J$121,Quarterly_Returns!$E$2:$E$121,$A12,Quarterly_Returns!$A$2:$A$121,8)+AVERAGEIFS(Quarterly_Returns!$J$2:$J$121,Quarterly_Returns!$E$2:$E$121,$A12,Quarterly_Returns!$A$2:$A$121,9)+AVERAGEIFS(Quarterly_Returns!$J$2:$J$121,Quarterly_Returns!$E$2:$E$121,$A12,Quarterly_Returns!$A$2:$A$121,10))/10,2) -> 7.92
A14: Correlation Matrix
B15: Bond | C15: Commodity | D15: Currency | E15: ETF | F15: Equity
A16: Bond | B16: =ROUND(CORREL($B5:$B12,$B5:$B12),2) -> 1 | C16: =ROUND(CORREL($B5:$B12,$C5:$C12),2) -> 0.26 | D16: =ROUND(CORREL($B5:$B12,$D5:$D12),2) -> 0.69 | E16: =ROUND(CORREL($B5:$B12,$E5:$E12),2) -> -0.08 | F16: =ROUND(CORREL($B5:$B12,$F5:$F12),2) -> 0.01
A17: Commodity | B17: =ROUND(CORREL($C5:$C12,$B5:$B12),2) -> 0.26 | C17: =ROUND(CORREL($C5:$C12,$C5:$C12),2) -> 1 | D17: =ROUND(CORREL($C5:$C12,$D5:$D12),2) -> 0.12 | E17: =ROUND(CORREL($C5:$C12,$E5:$E12),2) -> 0.25 | F17: =ROUND(CORREL($C5:$C12,$F5:$F12),2) -> 0.18
A18: Currency | B18: =ROUND(CORREL($D5:$D12,$B5:$B12),2) -> 0.69 | C18: =ROUND(CORREL($D5:$D12,$C5:$C12),2) -> 0.12 | D18: =ROUND(CORREL($D5:$D12,$D5:$D12),2) -> 1 | E18: =ROUND(CORREL($D5:$D12,$E5:$E12),2) -> -0.03 | F18: =ROUND(CORREL($D5:$D12,$F5:$F12),2) -> 0.53
A19: ETF | B19: =ROUND(CORREL($E5:$E12,$B5:$B12),2) -> -0.08 | C19: =ROUND(CORREL($E5:$E12,$C5:$C12),2) -> 0.25 | D19: =ROUND(CORREL($E5:$E12,$D5:$D12),2) -> -0.03 | E19: =ROUND(CORREL($E5:$E12,$E5:$E12),2) -> 1 | F19: =ROUND(CORREL($E5:$E12,$F5:$F12),2) -> 0.46
A20: Equity | B20: =ROUND(CORREL($F5:$F12,$B5:$B12),2) -> 0.01 | C20: =ROUND(CORREL($F5:$F12,$C5:$C12),2) -> 0.18 | D20: =ROUND(CORREL($F5:$F12,$D5:$D12),2) -> 0.53 | E20: =ROUND(CORREL($F5:$F12,$E5:$E12),2) -> 0.46 | F20: =ROUND(CORREL($F5:$F12,$F5:$F12),2) -> 1

Sheet PowerBI_Import_Data
A1: This sheet is a flat, clean table — import THIS sheet directly into Power BI (Get Data > Excel).
A2: trade_date | B2: ticker | C2: asset_class | D2: sector | E2: close_price | F2: daily_volume | G2: num_transactions | H2: total_transaction_value
A3: 2024-01-02 | B3: AAPL | C3: Equity | D3: Technology | E3: 271.46 | F3: 5736045 | G3: 2 | H3: 1070522.4
A4: 2024-01-03 | B4: AAPL | C4: Equity | D4: Technology | E4: 277.93 | F4: 3024459 | G4: 3 | H4: 1624727.8
A5: 2024-01-04 | B5: AAPL | C5: Equity | D5: Technology | E5: 279.88 | F5: 5972988 | G5: 0 | H5: 0
A6: 2024-01-05 | B6: AAPL | C6: Equity | D6: Technology | E6: 281.19 | F6: 4640304 | G6: 3 | H6: 3634883.4
A7: 2024-01-08 | B7: AAPL | C7: Equity | D7: Technology | E7: 284.62 | F7: 843682 | G7: 0 | H7: 0
A8: 2024-01-09 | B8: AAPL | C8: Equity | D8: Technology | E8: 278.44 | F8: 2245931 | G8: 3 | H8: 2721059.5
A9: 2024-01-10 | B9: AAPL | C9: Equity | D9: Technology | E9: 281.77 | F9: 2071302 | G9: 2 | H9: 1639219.6
A10: 2024-01-11 | B10: AAPL | C10: Equity | D10: Technology | E10: 284.26 | F10: 5068482 | G10: 4 | H10: 1851139.4
A11: 2024-01-12 | B11: AAPL | C11: Equity | D11: Technology | E11: 288.26 | F11: 5299998 | G11: 1 | H11: 588118.41
A12: 2024-01-15 | B12: AAPL | C12: Equity | D12: Technology | E12: 295.7 | F12: 6319999 | G12: 2 | H12: 2061129.6
A13: 2024-01-16 | B13: AAPL | C13: Equity | D13: Technology | E13: 295.95 | F13: 7571822 | G13: 4 | H13: 4138903.8
A14: 2024-01-17 | B14: AAPL | C14: Equity | D14: Technology | E14: 297.37 | F14: 3467239 | G14: 4 | H14: 2669460.9
... A7502: 2025-12-01 | B7502: UUP | C7502: Currency | D7502: Currency | E7502: 291.41 | F7502: 5592511 | G7502: 5 | H7502: 3954786.1
